Workbook

Sheet Read Me
B2: AI Inventory & Risk Register - Part 4 worked example
B3: AI Governance Series - github.com/NarendraKarki/ai-governance
B5: What this is
B6: The worked example from AI_Risk_Register_Walkthrough.md, turned into a working Excel workbook: a six-system AI inventory and its twenty-four-risk register for a synthetic retail group (Marsa Retail Group - fictional; nothing in it describes a real company). Two blank templates are included for building your own. Educational material, not legal advice - have your DPO or legal counsel review before adopting.
B8: How the workbook is organised
B9: Read Me - this sheet.
B10: Summary - live counts of risks by severity band and by system, calculated with formulas from the Risk Register sheet.
B11: AI Inventory - the six-system worked example.
B12: AI Risk Register - the twenty-four-risk worked example, with two calculated columns added.
B13: Inventory Template / Risk Register Template - blank rows to fill in, one example row each, fillable cells shaded yellow.
B15: The severity and likelihood scale (fixed, 1-4)
B16: Every rating in the Risk Register uses the same four-level scale, defined in words in section 6 (Step 5) of the walkthrough - a 1-4 number with no definition is how registers end up with everything rated 'medium'. Severity to people and severity to the organisation are rated on separate columns, deliberately: a risk that is low-cost to the organisation and severe for the individual it affects (a wrongly rejected job candidate, a customer wrongly flagged as a fraudster) must not be rated away by netting the two together. The top severity-to-people level is anchored to the outcomes the EU AI Act calls a 'serious incident' (Art 3(49)): death or serious harm to health, serious and irreversible disruption of critical infrastructure, infringement of a fundamental-rights obligation, or serious harm to property or the environment.
... B19: Risk score = severity x likelihood (1-16), calculated separately for people and for the organisation. The Band is the score sorted into four bands:
B20: Critical | C20: score >= 12
B21: High | C21: score >= 8
B22: Medium | C22: score >= 4
B23: Low | C23: score < 4
B25: Column glossary - AI Inventory
B26: System ID | C26: Short reference code for the system (S1, S2...). Links register rows back to it.
B27: Name | C27: Plain-language name of the system.
B28: Status | C28: Lifecycle state: in use / trial / retired.
B29: What it does | C29: One sentence a lay reader would understand, describing what the system does.
B30: Output & who acts on it | C30: What the system produces, and who acts on that output.
B31: Role (EU AI Act) | C31: The organisation's EU AI Act role for this system: provider, deployer, or both.
B32: Basis for role | C32: The reasoning behind the role - built in-house, bought as supplied, or bought and modified.
B33: Supplier | C33: The vendor, if the system was bought.
B34: Contract ref. | C34: Internal contract reference number.
B35: Technical ref. (model/version) | C35: The model or version identifier.
B36: Countries used in | C36: Countries where the system itself is used.
B37: Countries output used in | C37: Countries where the system's OUTPUT is acted on - this is what actually triggers the EU AI Act's reach, not where the servers sit.
... B52: Verified by | C52: Who checked it.
B54: Column glossary - AI Risk Register
B55: Risk ID | C55: Short reference code for the risk (R1, R2...).
B56: System ID | C56: Links this risk back to its row in the AI Inventory sheet.
B57: AI system (from inventory) | C57: The system's name, looked up from the AI Inventory sheet by System ID.
B58: Raised | C58: Date the risk was identified.
B59: Raised by | C59: Who identified it.
B60: IF (cause) | C60: The 'IF' clause: what could go wrong, technically or operationally.
B61: THEN (event) | C61: The 'THEN' clause: what happens as a result.
B62: Harm - what, to whom | C62: The consequence stated concretely - what harm, to whom - not a category.
...

Sheet Summary
B2: Summary
B3: Live counts, calculated from the AI Risk Register sheet.
B5: Residual band - severity to people x likelihood
B6: Band | C6: Count | D6: Share of all risks
B7: Critical | C7: =COUNTIF('AI Risk Register'!$AB$3:$AB$200,B7) -> 4 | D7: =C7/COUNTA('AI Risk Register'!$B$3:$B$200) -> 0.16666667
B8: High | C8: =COUNTIF('AI Risk Register'!$AB$3:$AB$200,B8) -> 3 | D8: =C8/COUNTA('AI Risk Register'!$B$3:$B$200) -> 0.125
B9: Medium | C9: =COUNTIF('AI Risk Register'!$AB$3:$AB$200,B9) -> 15 | D9: =C9/COUNTA('AI Risk Register'!$B$3:$B$200) -> 0.625
B10: Low | C10: =COUNTIF('AI Risk Register'!$AB$3:$AB$200,B10) -> 2 | D10: =C10/COUNTA('AI Risk Register'!$B$3:$B$200) -> 0.083333333
B11: Total risks | C11: =SUM(C7:C10) -> 24
B13: Per system
B14: System ID | C14: Name | D14: Risks | E14: Highest severity to people | F14: Open mitigations
B15: ='AI Inventory'!A3 -> S1 | C15: ='AI Inventory'!B3 -> Customer service assistant | D15: =COUNTIF('AI Risk Register'!$B$3:$B$200,B15) -> 6 | E15: =SUMPRODUCT(MAX(('AI Risk Register'!$B$3:$B$200=B15)*'AI Risk Register'!$K$3:$K$200)) -> 3 | F15: =COUNTIFS('AI Risk Register'!$B$3:$B$200,B15,'AI Risk Register'!$O$3:$O$200,"mitigate",'AI Risk Register'!$Z$3:$Z$200,"<>closed") -> 6
B16: ='AI Inventory'!A4 -> S2 | C16: ='AI Inventory'!B4 -> Candidate screening tool | D16: =COUNTIF('AI Risk Register'!$B$3:$B$200,B16) -> 5 | E16: =SUMPRODUCT(MAX(('AI Risk Register'!$B$3:$B$200=B16)*'AI Risk Register'!$K$3:$K$200)) -> 4 | F16: =COUNTIFS('AI Risk Register'!$B$3:$B$200,B16,'AI Risk Register'!$O$3:$O$200,"mitigate",'AI Risk Register'!$Z$3:$Z$200,"<>closed") -> 4
B17: ='AI Inventory'!A5 -> S3 | C17: ='AI Inventory'!B5 -> Payment fraud detection | D17: =COUNTIF('AI Risk Register'!$B$3:$B$200,B17) -> 4 | E17: =SUMPRODUCT(MAX(('AI Risk Register'!$B$3:$B$200=B17)*'AI Risk Register'!$K$3:$K$200)) -> 2 | F17: =COUNTIFS('AI Risk Register'!$B$3:$B$200,B17,'AI Risk Register'!$O$3:$O$200,"mitigate",'AI Risk Register'!$Z$3:$Z$200,"<>closed") -> 3
B18: ='AI Inventory'!A6 -> S4 | C18: ='AI Inventory'!B6 -> Demand forecasting | D18: =COUNTIF('AI Risk Register'!$B$3:$B$200,B18) -> 1 | E18: =SUMPRODUCT(MAX(('AI Risk Register'!$B$3:$B$200=B18)*'AI Risk Register'!$K$3:$K$200)) -> 1 | F18: =COUNTIFS('AI Risk Register'!$B$3:$B$200,B18,'AI Risk Register'!$O$3:$O$200,"mitigate",'AI Risk Register'!$Z$3:$Z$200,"<>closed") -> 0
B19: ='AI Inventory'!A7 -> S5 | C19: ='AI Inventory'!B7 -> Personalisation and promotions engine | D19: =COUNTIF('AI Risk Register'!$B$3:$B$200,B19) -> 4 | E19: =SUMPRODUCT(MAX(('AI Risk Register'!$B$3:$B$200=B19)*'AI Risk Register'!$K$3:$K$200)) -> 3 | F19: =COUNTIFS('AI Risk Register'!$B$3:$B$200,B19,'AI Risk Register'!$O$3:$O$200,"mitigate",'AI Risk Register'!$Z$3:$Z$200,"<>closed") -> 3
B20: ='AI Inventory'!A8 -> S6 | C20: ='AI Inventory'!B8 -> Shift optimiser | D20: =COUNTIF('AI Risk Register'!$B$3:$B$200,B20) -> 4 | E20: =SUMPRODUCT(MAX(('AI Risk Register'!$B$3:$B$200=B20)*'AI Risk Register'!$K$3:$K$200)) -> 4 | F20: =COUNTIFS('AI Risk Register'!$B$3:$B$200,B20,'AI Risk Register'!$O$3:$O$200,"mitigate",'AI Risk Register'!$Z$3:$Z$200,"<>closed") -> 4
B22: Note: 'Open mitigations' checks decision = mitigate and status <> closed on each system's rows.

Sheet AI Inventory
A1: AI Inventory | B1: Marsa Retail Group (synthetic) - worked example, six systems
A2: System ID | B2: Name | C2: Status | D2: What it does | E2: Output & who acts on it | F2: Role (EU AI Act) | G2: Basis for role | H2: Supplier | I2: Contract ref. | J2: Technical ref. (model/version) | K2: Countries used in | L2: Countries output used in | M2: People affected | N2: Data used | O2: ROP ref. | P2: EU AI Act tier | Q2: EU AI Act basis | R2: Derogation considered? | S2: Derogation claimed? | T2: Duties bind from | U2: Applies today | V2: Other law refs. | W2: Business owner | X2: Technical owner | Y2: Found by | Z2: Last verified | AA2: Verified by
A3: S1 | B3: Customer service assistant | C3: in use | D3: Answers customer questions about orders and returns on the website and app and drafts replies for agents | E3: Answers shown to customers directly and drafts for agents; customers act on answers | F3: deployer | G3: Bought and used as supplied; group has changed prompts and knowledge base only | H3: Helix Assist (synthetic) | I3: CON-2025-031 | J3: Helix Assist v4 on vendor-hosted general-purpose model | K3: GB, BH, SA, AE, IN, SG, AU, NL | L3: GB, BH, SA, AE, IN, SG, AU, NL | M3: Customers of the group | N3: Chat transcripts, order references, delivery addresses | O3: ROP-017 | P3: transparency | Q3: Art 50(1) - system intended to interact directly with natural persons; provider design duty; deployer must not remove the disclosure | R3: no | S3: no | T3: 2026-08-02 (transparency); AI literacy 2025-02-02 | U3: AI literacy; transparency | V3: Part 1 policies: UK; BH; SA; AE; IN; SG; AU; EU (data protection and transparency) | W3: Head of Customer Operations | X3: Digital Platforms Lead | Y3: procurement | Z3: 2026-09-14 | AA3: AI governance lead
A4: S2 | B4: Candidate screening tool | C4: in use | D4: Ranks and filters job applications against the vacancy before a recruiter sees them | E4: Ranked shortlist to recruiters; applications below a rank threshold are rejected automatically | F4: deployer | G4: Bought and used as supplied; role-drift request (promotion ranking) withdrawn 2026-09-10 | H4: TalentRank (synthetic) | I4: CON-2024-112 | J4: TalentRank SaaS release 2026.3 | K4: GB, BH, SA, AE, IN, SG, AU, NL | L4: GB, BH, SA, AE, IN, SG, AU, NL | M4: Job applicants including applicants to the EU subsidiary; employees if the promotion feature had been enabled | N4: CVs, application forms, assessment scores | O4: ROP-041 | P4: high-risk | Q4: Annex III point 4(a) - recruitment or selection: analyse and filter job applications and evaluate candidates | R4: yes | S4: no | T4: 2027-12-02 (high-risk); AI literacy 2025-02-02 | U4: AI literacy | V4: Part 1 policies: UK; BH; SA; AE; IN; SG; AU; EU (data protection incl. automated decisions and DPIA) | W4: Group HR Director | X4: HR Systems Manager | Y4: procurement | Z4: 2026-09-14 | AA4: AI governance lead
A5: S3 | B5: Payment fraud detection | C5: in use | D5: Scores each e-commerce order for fraud risk and holds orders above a threshold for review | E5: Hold or release decision; holds go to the payments team; releases are automatic | F5: both | G5: Built in-house and used in-house | H5: none | I5: n/a | J5: fraud-gbm v7 (in-house) | K5: GB, SA, AE, SG, AU, NL | L5: GB, SA, AE, SG, AU, NL | M5: Customers of the e-commerce sites | N5: Order, payment, device and delivery data | O5: ROP-009 | P5: none | Q5: Not listed in Annex III (fraud detection is not a listed use; the 5(b) credit-scoring listing expressly excludes financial fraud detection). Not a prohibited practice. Not a transparency case | R5: no | S5: no | T5: AI literacy 2025-02-02 | U5: AI literacy | V5: Part 1 policies: UK; SA; AE; SG; AU; EU (profiling and automated decisions) | W5: Head of Payments | X5: Data Science Lead | Y5: data platform | Z5: 2026-09-14 | AA5: AI governance lead
A6: S4 | B6: Demand forecasting | C6: in use | D6: Forecasts weekly demand per product per store to drive replenishment orders | E6: Replenishment quantities to the supply chain team; orders placed automatically below a value threshold | F6: both | G6: Built in-house and used in-house | H6: none | I6: n/a | J6: forecast-v3 (in-house) | K6: GB, BH, SA, AE, IN, SG, AU, NL | L6: GB, BH, SA, AE, IN, SG, AU, NL | M6: None - no decisions about natural persons | N6: Sales history, stock levels, calendar and promotions data | O6: n/a | P6: none | Q6: Not listed; no natural persons subject to its output | R6: no | S6: no | T6: AI literacy 2025-02-02 | U6: AI literacy | V6: n/a | W6: Head of Supply Chain | X6: Data Science Lead | Y6: data platform | Z6: 2026-09-14 | AA6: AI governance lead
A7: S5 | B7: Personalisation and promotions engine | C7: in use | D7: Selects which offers and prices each customer sees on the e-commerce sites and in email | E7: Offer and price shown to each customer; no human in the loop | F7: deployer | G7: Bought and used as supplied; group supplies its own customer features | H7: Lumen Offers (synthetic) | I7: MKT-2025-007 (marketing contract; not in the procurement AI list) | J7: Lumen Offers cloud; vendor model | K7: GB, SA, AE, SG, AU, NL | L7: GB, SA, AE, SG, AU, NL | M7: Customers of the e-commerce sites | N7: Browsing, purchase history, device, location, loyalty data | O7: ROP-022 | P7: none | Q7: Not listed in Annex III. Screened against Art 5(1)(a) and (b): urgency-prompt feature targeting behavioural signals could approach the vulnerability-exploitation prohibition if it targets a specific social or economic situation and causes significant harm; feature disabled pending assessment (R16) | R7: no | S7: no | T7: AI literacy 2025-02-02 | U7: AI literacy | V7: Part 1 policies: UK; SA; AE; SG; AU; EU (profiling; consumer-law disclosure of personalised pricing - not verified for this artifact) | W7: Chief Marketing Officer | X7: Marketing Technology Lead | Y7: function questionnaire | Z7: 2026-09-14 | AA7: AI governance lead
A8: S6 | B8: Shift optimiser | C8: in use | D8: Allocates shifts to store staff using availability and individual performance scores inside the workforce management suite | E8: Published rota; store managers may edit before publishing but rarely do | F8: deployer | G8: Bought as part of the workforce management suite; feature enabled by vendor update 2025-07; not reviewed at the time | H8: ShiftWise (synthetic) | I8: CON-2023-058 (workforce management; AI feature not in the contract description) | J8: ShiftWise WFM 11.2 - Optimise module | K8: GB, BH, SA, AE, IN, SG, AU, NL | L8: GB, BH, SA, AE, IN, SG, AU, NL | M8: Store employees including employees of the EU subsidiary | N8: Availability, contracted hours, sales-per-hour and attendance scores | O8: ROP-033 (does not yet mention the optimiser) | P8: high-risk | Q8: Annex III point 4(b) - decisions affecting terms of work-related relationships and allocation of tasks based on individual behaviour or characteristics; applies to the EU subsidiary's use | R8: yes | S8: no | T8: 2027-12-02 (high-risk); AI literacy 2025-02-02 | U8: AI literacy | V8: Part 1 policies: UK; BH; SA; AE; IN; SG; AU; EU (employee data; works council information) | W8: Group Retail Operations Director | X8: Workforce Systems Manager | Y8: SaaS console sweep | Z8: 2026-09-14 | AA8: AI governance lead

Sheet AI Risk Register
A1: AI Risk Register | B1: Twenty-two risks across the six systems above
A2: Risk ID | B2: System ID | C2: AI system (from inventory) | D2: Raised | E2: Raised by | F2: IF (cause) | G2: THEN (event) | H2: Harm - what, to whom | I2: Harm category | J2: Existing controls | K2: Severity to people (1-4) | L2: Severity to org. (1-4) | M2: Likelihood (1-4) | N2: Justification | O2: Decision | P2: Decided by | Q2: Decided on | R2: Mitigation | S2: Mitigation owner | T2: Mitigation due | U2: Indicator | V2: Indicator threshold | W2: Watched by | X2: Review triggers | Y2: Next review | Z2: Status | AA2: Risk score - people | AB2: Band - people | AC2: Risk score - org. | AD2: Band - org.
A3: R1 | B3: S1 | C3: =IFERROR(INDEX('AI Inventory'!$B$3:$B$200,MATCH(B3,'AI Inventory'!$A$3:$A$200,0)),"") -> Customer service assistant | D3: 2026-09-14 | E3: AI governance lead | F3: the assistant states a returns or refund rule that is not the group's policy | G3: customers act on it and are refused at the store or online | H3: financial loss to the customer - recoverable on complaint | I3: wrong decision | J3: Knowledge base reviewed monthly; agents can override | K3: 2 | L3: 2 | M3: 3 | N3: People 2: loss is recoverable on complaint. Org 2: complaint volume and goodwill refunds. Likelihood 3: two confirmed cases in the last quarter | O3: mitigate | P3: Head of Customer Operations | Q3: 2026-09-16 | R3: Policy answers grounded to the published policy pages only; assistant declines to state refund amounts; weekly sample review of 50 policy answers | S3: Digital Platforms Lead | T3: 2026-11-30 | U3: Complaints tagged 'assistant gave wrong policy' per month | V3: More than 3 per month | W3: Customer Operations quality lead | X3: vendor model update; policy change; complaint pattern | Y3: 2026-12-14 | Z3: mitigating | AA3: =K3*M3 -> 6 | AB3: =IF(AA3>=12,"Critical",IF(AA3>=8,"High",IF(AA3>=4,"Medium","Low"))) -> Medium | AC3: =L3*M3 -> 6 | AD3: =IF(AC3>=12,"Critical",IF(AC3>=8,"High",IF(AC3>=4,"Medium","Low"))) -> Medium
A4: R2 | B4: S1 | C4: =IFERROR(INDEX('AI Inventory'!$B$3:$B$200,MATCH(B4,'AI Inventory'!$A$3:$A$200,0)),"") -> Customer service assistant | D4: 2026-09-14 | E4: Privacy officer | F4: customers paste card numbers or full order and address details into the chat | G4: transcripts containing that data are retained by the vendor beyond the contracted purpose and period | H4: disclosure of customers' personal and payment data | I4: data | J4: Contract clause on transcript retention (90 days); no input filtering | K4: 3 | L4: 3 | M4: 2 | N4: People 3: disclosure of payment data. Org 3: data protection enforcement in any of eight jurisdictions. Likelihood 2: vendor retention confirmed contractually; no breach known | O4: mitigate | P4: Head of Customer Operations | Q4: 2026-09-16 | R4: Input redaction of card patterns before transmission; transcript retention reduced to 30 days; annual vendor attestation | S4: Digital Platforms Lead | T4: 2026-12-31 | U4: Redaction hits per week (card patterns caught) | V4: Any unredacted card pattern found in vendor-side sample | W4: Privacy officer | X4: vendor contract change; vendor incident notice; retention audit | Y4: 2026-12-14 | Z4: mitigating | AA4: =K4*M4 -> 6 | AB4: =IF(AA4>=12,"Critical",IF(AA4>=8,"High",IF(AA4>=4,"Medium","Low"))) -> Medium | AC4: =L4*M4 -> 6 | AD4: =IF(AC4>=12,"Critical",IF(AC4>=8,"High",IF(AC4>=4,"Medium","Low"))) -> Medium
A5: R3 | B5: S1 | C5: =IFERROR(INDEX('AI Inventory'!$B$3:$B$200,MATCH(B5,'AI Inventory'!$A$3:$A$200,0)),"") -> Customer service assistant | D5: 2026-09-14 | E5: AI governance lead | F5: a website or app redesign removes or hides the 'you are talking to an AI assistant' notice | G5: customers are not told they are interacting with an AI system | H5: customers cannot calibrate trust in what they are told; transparency-duty breach | I5: manipulation | J5: Notice present today; no change control on it | K5: 2 | L5: 3 | M5: 2 | N5: People 2: customers misled about who they are talking to. Org 3: transparency duty in force since 2 Aug 2026. Likelihood 2: redesign scheduled Q1 2027 | O5: mitigate | P5: Head of Customer Operations | Q5: 2026-09-16 | R5: Notice added to the release checklist as a required element; automated UI test asserts its presence | S5: Digital Platforms Lead | T5: 2026-10-31 | U5: UI test result per release | V5: Any failure | W5: Digital Platforms Lead | X5: UI release; vendor UI change | Y5: 2027-03-14 | Z5: mitigating | AA5: =K5*M5 -> 4 | AB5: =IF(AA5>=12,"Critical",IF(AA5>=8,"High",IF(AA5>=4,"Medium","Low"))) -> Medium | AC5: =L5*M5 -> 6 | AD5: =IF(AC5>=12,"Critical",IF(AC5>=8,"High",IF(AC5>=4,"Medium","Low"))) -> Medium
A6: R4 | B6: S1 | C6: =IFERROR(INDEX('AI Inventory'!$B$3:$B$200,MATCH(B6,'AI Inventory'!$A$3:$A$200,0)),"") -> Customer service assistant | D6: 2026-09-14 | E6: AI governance lead | F6: the vendor changes the underlying model without notice | G6: answer quality and tone change and the group's tests no longer describe the system in use | H6: customers receive worse or different answers; the group's records describe a system that no longer exists | I6: wrong decision | J6: Vendor notifies 'material changes' under the contract; term undefined | K6: 2 | L6: 2 | M6: 3 | N6: People 2: answer quality. Org 2: records out of date. Likelihood 3: vendor has changed the base model twice in 18 months | O6: mitigate | P6: Head of Customer Operations | Q6: 2026-09-16 | R6: Contract addendum defining model change as a material change with 30 days' notice; regression test set of 200 questions re-run on notice | S6: Digital Platforms Lead | T6: 2027-01-31 | U6: Regression pass rate after each notified change | V6: Below 95% | W6: Digital Platforms Lead | X6: vendor model update; contract renewal | Y6: 2026-12-14 | Z6: mitigating | AA6: =K6*M6 -> 6 | AB6: =IF(AA6>=12,"Critical",IF(AA6>=8,"High",IF(AA6>=4,"Medium","Low"))) -> Medium | AC6: =L6*M6 -> 6 | AD6: =IF(AC6>=12,"Critical",IF(AC6>=8,"High",IF(AC6>=4,"Medium","Low"))) -> Medium
A7: R5 | B7: S2 | C7: =IFERROR(INDEX('AI Inventory'!$B$3:$B$200,MATCH(B7,'AI Inventory'!$A$3:$A$200,0)),"") -> Candidate screening tool | D7: 2026-09-14 | E7: Group HR Director | F7: the tool's training data reflects the historical gender balance of store and sales roles | G7: women applying for sales roles are ranked lower than men with equivalent qualifications | H7: qualified candidates rejected without a human seeing the application; potential unlawful discrimination | I7: unfair decision | J7: Vendor's fairness statement (no test data supplied); no group-side testing | K7: 4 | L7: 3 | M7: 3 | N7: People 4: unlawful discriminatory rejection would infringe Union-law obligations protecting fundamental rights - a serious-incident outcome. Org 3: equality-law and AI Act enforcement. Likelihood 3: no evidence either way; the vendor's statement is untested and the training population is known to be skewed | O7: mitigate | P7: Group HR Director | Q7: 2026-09-16 | R7: Bias test on the last 12 months of group applications using the Part 3 protocol; vendor asked for per-group performance figures under the instructions-for-use duty; rank threshold suspended for sales roles until results are in | S7: HR Systems Manager | T7: 2027-01-31 | U7: Shortlist rate by sex per role family | V7: Ratio below 0.80 or gap above 10 points | W7: HR Systems Manager | X7: retrain or vendor update; new role family; complaint; quarterly | Y7: 2026-12-14 | Z7: mitigating | AA7: =K7*M7 -> 12 | AB7: =IF(AA7>=12,"Critical",IF(AA7>=8,"High",IF(AA7>=4,"Medium","Low"))) -> Critical | AC7: =L7*M7 -> 9 | AD7: =IF(AC7>=12,"Critical",IF(AC7>=8,"High",IF(AC7>=4,"Medium","Low"))) -> High
A8: R6 | B8: S2 | C8: =IFERROR(INDEX('AI Inventory'!$B$3:$B$200,MATCH(B8,'AI Inventory'!$A$3:$A$200,0)),"") -> Candidate screening tool | D8: 2026-09-14 | E8: Privacy officer | F8: applications below the rank threshold are rejected automatically with no recruiter review | G8: rejection decisions are solely automated | H8: candidates cannot contest a decision no person made; automated-decision rights engaged for EU applicants | I8: uncontestable decision | J8: None - threshold rejection has been on since 2024 | K8: 4 | L8: 3 | M8: 4 | N8: People 4: a solely automated rejection without the safeguards data protection law requires would infringe Union-law obligations protecting fundamental rights. Org 3: data protection enforcement. Likelihood 4: it is happening now | O8: mitigate | P8: Group HR Director | Q8: 2026-09-16 | R8: Automatic rejection switched off; below-threshold applications reviewed by a recruiter with a stated minimum time; rejection notice includes the route to ask for reconsideration | S8: HR Systems Manager | T8: 2026-10-15 | U8: Share of rejections with a recorded recruiter review | V8: Below 100% | W8: HR Systems Manager | X8: process change; vendor update; quarterly | Y8: 2026-12-14 | Z8: mitigating | AA8: =K8*M8 -> 16 | AB8: =IF(AA8>=12,"Critical",IF(AA8>=8,"High",IF(AA8>=4,"Medium","Low"))) -> Critical | AC8: =L8*M8 -> 12 | AD8: =IF(AC8>=12,"Critical",IF(AC8>=8,"High",IF(AC8>=4,"Medium","Low"))) -> Critical
A9: R7 | B9: S2 | C9: =IFERROR(INDEX('AI Inventory'!$B$3:$B$200,MATCH(B9,'AI Inventory'!$A$3:$A$200,0)),"") -> Candidate screening tool | D9: 2026-09-14 | E9: AI governance lead | F9: the instructions for use and the provider's EU database registration are not obtained before the high-risk duties bind | G9: the group uses a high-risk system without the instructions the deployer duties are framed around | H9: candidates subject to a system used outside its assessed conditions; deployer in breach from 2 Dec 2027 | I9: wrong decision | J9: None | K9: 2 | L9: 3 | M9: 3 | N9: People 2: indirect. Org 3: deployer duties unmet on the binding date. Likelihood 3: vendor has not yet answered the request | O9: mitigate | P9: Group HR Director | Q9: 2026-09-16 | R9: Written request to the vendor for instructions for use and registration timetable; contract renewal made conditional on both; fallback assessment of alternative tools by mid-2027 | S9: HR Systems Manager | T9: 2027-06-30 | U9: Vendor response received | V9: Not received by 2027-03-31 | W9: AI governance lead | X9: vendor response; law or guidance change; 2027-06-30 | Y9: 2027-03-14 | Z9: open | AA9: =K9*M9 -> 6 | AB9: =IF(AA9>=12,"Critical",IF(AA9>=8,"High",IF(AA9>=4,"Medium","Low"))) -> Medium | AC9: =L9*M9 -> 9 | AD9: =IF(AC9>=12,"Critical",IF(AC9>=8,"High",IF(AC9>=4,"Medium","Low"))) -> High
A10: R8 | B10: S2 | C10: =IFERROR(INDEX('AI Inventory'!$B$3:$B$200,MATCH(B10,'AI Inventory'!$A$3:$A$200,0)),"") -> Candidate screening tool | D10: 2026-09-10 | E10: AI governance lead | F10: HR enables the vendor's proposed promotion-ranking feature configured on the group's own criteria | G10: the group becomes the provider of a high-risk system (promotion decisions) that no one has assessed | H10: employees ranked for promotion by an unassessed system; provider duties inherited without a quality management system | I10: unfair decision | J10: Feature request withdrawn 2026-09-10 | K10: 3 | L10: 3 | M10: 2 | N10: People 3: lasting effect on employees' careers. Org 3: provider duties without the means to meet them. Likelihood 2: withdrawn; could be re-raised | O10: avoid | P10: Group HR Director | Q10: 2026-09-10 | R10: Feature not enabled; any future promotion tooling goes through the inventory as a new system with its own classification | S10: Group HR Director | T10: 2026-09-10 | U10: New-system requests naming promotion or performance | V10: Any | W10: AI governance lead | X10: new use requested | Y10: 2027-03-14 | Z10: closed | AA10: =K10*M10 -> 6 | AB10: =IF(AA10>=12,"Critical",IF(AA10>=8,"High",IF(AA10>=4,"Medium","Low"))) -> Medium | AC10: =L10*M10 -> 6 | AD10: =IF(AC10>=12,"Critical",IF(AC10>=8,"High",IF(AC10>=4,"Medium","Low"))) -> Medium
A11: R9 | B11: S2 | C11: =IFERROR(INDEX('AI Inventory'!$B$3:$B$200,MATCH(B11,'AI Inventory'!$A$3:$A$200,0)),"") -> Candidate screening tool | D11: 2026-09-14 | E11: Privacy officer | F11: EU applicants are not told that an AI system is used to filter their application | G11: applicants are unaware and cannot exercise their rights | H11: candidates uninformed; deployer information duty unmet from 2 Dec 2027 and data-protection transparency unmet now | I11: uncontestable decision | J11: Privacy notice mentions 'automated tools' generically | K11: 2 | L11: 2 | M11: 3 | N11: People 2: awareness. Org 2: notice deficiency. Likelihood 3: current notice is generic | O11: mitigate | P11: Group HR Director | Q11: 2026-09-16 | R11: Application-form notice naming the tool and its role; privacy notice updated | S11: HR Systems Manager | T11: 2026-10-31 | U11: Notice present on all application routes | V11: Any route without it | W11: Privacy officer | X11: new application route; law or guidance change | Y11: 2026-12-14 | Z11: mitigating | AA11: =K11*M11 -> 6 | AB11: =IF(AA11>=12,"Critical",IF(AA11>=8,"High",IF(AA11>=4,"Medium","Low"))) -> Medium | AC11: =L11*M11 -> 6 | AD11: =IF(AC11>=12,"Critical",IF(AC11>=8,"High",IF(AC11>=4,"Medium","Low"))) -> Medium
A12: R10 | B12: S3 | C12: =IFERROR(INDEX('AI Inventory'!$B$3:$B$200,MATCH(B12,'AI Inventory'!$A$3:$A$200,0)),"") -> Payment fraud detection | D12: 2026-09-14 | E12: Head of Payments | F12: the model's false-positive rate is higher for first-time customers and for deliveries to certain postcode bands | G12: legitimate orders from those customers are held for review more often | H12: delay and refusal for legitimate customers concentrated in identifiable groups | I12: unfair decision | J12: Held orders reviewed by the payments team within 24 hours | K12: 2 | L12: 2 | M12: 3 | N12: People 2: delay; recoverable. Org 2: lost sales and complaints. Likelihood 3: hold rate for first-time customers is 3.1 times the base rate | O12: mitigate | P12: Head of Payments | Q12: 2026-09-16 | R12: Hold rate and false-positive rate monitored by customer tenure and postcode band; threshold reviewed against the Part 3 protocol quarterly | S12: Data Science Lead | T12: 2026-11-30 | U12: False-positive rate by tenure and postcode band | V12: Any band above 2 times the overall rate | W12: Data Science Lead | X12: retrain; threshold change; quarterly | Y12: 2026-12-14 | Z12: mitigating | AA12: =K12*M12 -> 6 | AB12: =IF(AA12>=12,"Critical",IF(AA12>=8,"High",IF(AA12>=4,"Medium","Low"))) -> Medium | AC12: =L12*M12 -> 6 | AD12: =IF(AC12>=12,"Critical",IF(AC12>=8,"High",IF(AC12>=4,"Medium","Low"))) -> Medium
A13: R11 | B13: S3 | C13: =IFERROR(INDEX('AI Inventory'!$B$3:$B$200,MATCH(B13,'AI Inventory'!$A$3:$A$200,0)),"") -> Payment fraud detection | D13: 2026-09-14 | E13: Head of Payments | F13: a new fraud pattern emerges that the training data does not contain | G13: fraud losses rise until the model is retrained | H13: financial loss to the group | I13: none | J13: Monthly retrain; chargeback monitoring | K13: 1 | L13: 3 | M13: 3 | N13: People 1: no harm to customers from a miss. Org 3: chargeback losses. Likelihood 3: pattern shifts seen twice a year | O13: accept | P13: Head of Payments | Q13: 2026-09-16 | R13: n/a - accepted with monthly retrain and chargeback monitoring as existing controls | S13: n/a | T13: n/a | U13: Chargeback rate per week | V13: Above 0.4% for two consecutive weeks | W13: Head of Payments | X13: chargeback spike; quarterly | Y13: 2026-12-14 | Z13: accepted | AA13: =K13*M13 -> 3 | AB13: =IF(AA13>=12,"Critical",IF(AA13>=8,"High",IF(AA13>=4,"Medium","Low"))) -> Low | AC13: =L13*M13 -> 9 | AD13: =IF(AC13>=12,"Critical",IF(AC13>=8,"High",IF(AC13>=4,"Medium","Low"))) -> High
A14: R12 | B14: S3 | C14: =IFERROR(INDEX('AI Inventory'!$B$3:$B$200,MATCH(B14,'AI Inventory'!$A$3:$A$200,0)),"") -> Payment fraud detection | D14: 2026-09-14 | E14: Privacy officer | F14: a held order is cancelled automatically after 48 hours without a person reviewing it | G14: the cancellation is a solely automated decision | H14: EU customers lose an order with no human involvement and no route to contest | I14: uncontestable decision | J14: Payments team reviews holds within 24 hours in practice; auto-cancel remains configured | K14: 2 | L14: 2 | M14: 2 | N14: People 2: order loss; recoverable. Org 2: automated-decision rules. Likelihood 2: reviews are usually completed in time | O14: mitigate | P14: Head of Payments | Q14: 2026-09-16 | R14: Auto-cancel disabled; unreviewed holds escalate to a person instead | S14: Data Science Lead | T14: 2026-10-15 | U14: Count of auto-cancelled orders per week | V14: Any | W14: Head of Payments | X14: process change | Y14: 2026-12-14 | Z14: mitigating | AA14: =K14*M14 -> 4 | AB14: =IF(AA14>=12,"Critical",IF(AA14>=8,"High",IF(AA14>=4,"Medium","Low"))) -> Medium | AC14: =L14*M14 -> 4 | AD14: =IF(AC14>=12,"Critical",IF(AC14>=8,"High",IF(AC14>=4,"Medium","Low"))) -> Medium
... A26: R24 | B26: S3 | C26: =IFERROR(INDEX('AI Inventory'!$B$3:$B$200,MATCH(B26,'AI Inventory'!$A$3:$A$200,0)),"") -> Payment fraud detection | D26: 2026-09-21 | E26: Information security lead | F26: an organised fraud group probes the model with many small orders to learn which features and thresholds trigger a hold | G26: fraudulent orders are shaped to score just below the threshold and are released automatically | H26: fraud loss and chargebacks to the group; legitimate customers held more often when the threshold is tightened in response | I26: wrong decision | J26: Velocity limits per card and delivery address; model retrained quarterly; holds reviewed by the payments team; no adversarial cases in the evaluation set | K26: 2 | L26: 3 | M26: 3 | N26: People 2: legitimate customers delayed if the threshold is tightened in response. Org 3: direct fraud loss and chargebacks. Likelihood 3: threshold probing is a known pattern and the model's features are stable between retrains | O26: mitigate | P26: Head of Payments | Q26: 2026-09-21 | R26: Randomised holds on a sample of orders scoring just below the threshold; probing-pattern detection across order sequences by card, device and address; adversarial test cases added to the retraining evaluation | S26: Fraud Analytics Lead | T26: 2027-01-31 | U26: Approved-then-charged-back rate for orders scoring within ten points below the threshold | V26: Rate for that band exceeds twice the overall approved-order rate | W26: Head of Payments | X26: retrain; chargeback pattern; new payment method; change to the scoring features | Y26: 2026-12-14 | Z26: mitigating | AA26: =K26*M26 -> 6 | AB26: =IF(AA26>=12,"Critical",IF(AA26>=8,"High",IF(AA26>=4,"Medium","Low"))) -> Medium | AC26: =L26*M26 -> 9 | AD26: =IF(AC26>=12,"Critical",IF(AC26>=8,"High",IF(AC26>=4,"Medium","Low"))) -> High
A28: Risk score = severity x likelihood. Bands: 12-16 Critical, 8-9 High, 4-6 Medium, 1-3 Low.

Sheet Inventory Template
A1: Inventory Template | B1: One example row (yellow) - delete it and add your own systems below
A2: System ID | B2: Name | C2: Status | D2: What it does | E2: Output & who acts on it | F2: Role (EU AI Act) | G2: Basis for role | H2: Supplier | I2: Contract ref. | J2: Technical ref. (model/version) | K2: Countries used in | L2: Countries output used in | M2: People affected | N2: Data used | O2: ROP ref. | P2: EU AI Act tier | Q2: EU AI Act basis | R2: Derogation considered? | S2: Derogation claimed? | T2: Duties bind from | U2: Applies today | V2: Other law refs. | W2: Business owner | X2: Technical owner | Y2: Found by | Z2: Last verified | AA2: Verified by
A3: S1 | B3: e.g. Candidate screening tool | C3: in use | D3: e.g. Ranks and filters job applications before a recruiter sees them | E3: e.g. Ranked shortlist to recruiters; low-ranked applications rejected automatically | F3: deployer | G3: e.g. Bought and used as supplied | H3: e.g. Vendor name | I3: e.g. CON-2024-001 | J3: e.g. Product name and version | K3: e.g. UK, EU | L3: e.g. UK, EU | M3: e.g. Job applicants | N3: e.g. CVs, application forms | O3: e.g. ROP-001 | P3: high-risk | Q3: e.g. Annex III point 4(a) | R3: yes | S3: no | T3: e.g. 2027-12-02 (high-risk) | U3: e.g. AI literacy | V3: e.g. Part 1 policy reference | W3: e.g. Group HR Director | X3: e.g. HR Systems Manager | Y3: e.g. procurement | Z3: YYYY-MM-DD | AA3: e.g. your name/role

Sheet Risk Register Template
A1: Risk Register Template | B1: One example row (yellow) with live score/band formulas - delete it and add your own risks below
A2: Risk ID | B2: System ID | C2: AI system (from inventory) | D2: Raised | E2: Raised by | F2: IF (cause) | G2: THEN (event) | H2: Harm - what, to whom | I2: Harm category | J2: Existing controls | K2: Severity to people (1-4) | L2: Severity to org. (1-4) | M2: Likelihood (1-4) | N2: Justification | O2: Decision | P2: Decided by | Q2: Decided on | R2: Mitigation | S2: Mitigation owner | T2: Mitigation due | U2: Indicator | V2: Indicator threshold | W2: Watched by | X2: Review triggers | Y2: Next review | Z2: Status | AA2: Risk score - people | AB2: Band - people | AC2: Risk score - org. | AD2: Band - org.
A3: R1 | B3: S1 | C3: =IFERROR(INDEX('Inventory Template'!$B$3:$B$200,MATCH(B3,'Inventory Template'!$A$3:$A$200,0)),"") -> e.g. Candidate screening tool | D3: YYYY-MM-DD | E3: e.g. your name/role | F3: e.g. the training data reflects a historical imbalance | G3: e.g. the model ranks one group lower for a role | H3: e.g. qualified candidates rejected without human review | I3: unfair decision | J3: e.g. none yet / describe | K3: 3 | L3: 2 | M3: 2 | N3: e.g. People 3: ... Org 2: ... Likelihood 2: ... | O3: mitigate | P3: e.g. named role | Q3: YYYY-MM-DD | R3: e.g. named control | S3: e.g. named role | T3: YYYY-MM-DD | U3: e.g. a measure already collected | V3: e.g. a number | W3: e.g. named role | X3: e.g. vendor model update; complaint pattern | Y3: YYYY-MM-DD | Z3: open | AA3: =IF(OR(K3="",M3=""),"",K3*M3) -> 6 | AB3: =IF(AA3="","",IF(AA3>=12,"Critical",IF(AA3>=8,"High",IF(AA3>=4,"Medium","Low")))) -> Medium | AC3: =IF(OR(L3="",M3=""),"",L3*M3) -> 4 | AD3: =IF(AC3="","",IF(AC3>=12,"Critical",IF(AC3>=8,"High",IF(AC3>=4,"Medium","Low")))) -> Medium
C4: =IFERROR(INDEX('Inventory Template'!$B$3:$B$200,MATCH(B4,'Inventory Template'!$A$3:$A$200,0)),"") | AA4: =IF(OR(K4="",M4=""),"",K4*M4) | AB4: =IF(AA4="","",IF(AA4>=12,"Critical",IF(AA4>=8,"High",IF(AA4>=4,"Medium","Low")))) | AC4: =IF(OR(L4="",M4=""),"",L4*M4) | AD4: =IF(AC4="","",IF(AC4>=12,"Critical",IF(AC4>=8,"High",IF(AC4>=4,"Medium","Low"))))
C5: =IFERROR(INDEX('Inventory Template'!$B$3:$B$200,MATCH(B5,'Inventory Template'!$A$3:$A$200,0)),"") | AA5: =IF(OR(K5="",M5=""),"",K5*M5) | AB5: =IF(AA5="","",IF(AA5>=12,"Critical",IF(AA5>=8,"High",IF(AA5>=4,"Medium","Low")))) | AC5: =IF(OR(L5="",M5=""),"",L5*M5) | AD5: =IF(AC5="","",IF(AC5>=12,"Critical",IF(AC5>=8,"High",IF(AC5>=4,"Medium","Low"))))
C6: =IFERROR(INDEX('Inventory Template'!$B$3:$B$200,MATCH(B6,'Inventory Template'!$A$3:$A$200,0)),"") | AA6: =IF(OR(K6="",M6=""),"",K6*M6) | AB6: =IF(AA6="","",IF(AA6>=12,"Critical",IF(AA6>=8,"High",IF(AA6>=4,"Medium","Low")))) | AC6: =IF(OR(L6="",M6=""),"",L6*M6) | AD6: =IF(AC6="","",IF(AC6>=12,"Critical",IF(AC6>=8,"High",IF(AC6>=4,"Medium","Low"))))
C7: =IFERROR(INDEX('Inventory Template'!$B$3:$B$200,MATCH(B7,'Inventory Template'!$A$3:$A$200,0)),"") | AA7: =IF(OR(K7="",M7=""),"",K7*M7) | AB7: =IF(AA7="","",IF(AA7>=12,"Critical",IF(AA7>=8,"High",IF(AA7>=4,"Medium","Low")))) | AC7: =IF(OR(L7="",M7=""),"",L7*M7) | AD7: =IF(AC7="","",IF(AC7>=12,"Critical",IF(AC7>=8,"High",IF(AC7>=4,"Medium","Low"))))
C8: =IFERROR(INDEX('Inventory Template'!$B$3:$B$200,MATCH(B8,'Inventory Template'!$A$3:$A$200,0)),"") | AA8: =IF(OR(K8="",M8=""),"",K8*M8) | AB8: =IF(AA8="","",IF(AA8>=12,"Critical",IF(AA8>=8,"High",IF(AA8>=4,"Medium","Low")))) | AC8: =IF(OR(L8="",M8=""),"",L8*M8) | AD8: =IF(AC8="","",IF(AC8>=12,"Critical",IF(AC8>=8,"High",IF(AC8>=4,"Medium","Low"))))
C9: =IFERROR(INDEX('Inventory Template'!$B$3:$B$200,MATCH(B9,'Inventory Template'!$A$3:$A$200,0)),"") | AA9: =IF(OR(K9="",M9=""),"",K9*M9) | AB9: =IF(AA9="","",IF(AA9>=12,"Critical",IF(AA9>=8,"High",IF(AA9>=4,"Medium","Low")))) | AC9: =IF(OR(L9="",M9=""),"",L9*M9) | AD9: =IF(AC9="","",IF(AC9>=12,"Critical",IF(AC9>=8,"High",IF(AC9>=4,"Medium","Low"))))
C10: =IFERROR(INDEX('Inventory Template'!$B$3:$B$200,MATCH(B10,'Inventory Template'!$A$3:$A$200,0)),"") | AA10: =IF(OR(K10="",M10=""),"",K10*M10) | AB10: =IF(AA10="","",IF(AA10>=12,"Critical",IF(AA10>=8,"High",IF(AA10>=4,"Medium","Low")))) | AC10: =IF(OR(L10="",M10=""),"",L10*M10) | AD10: =IF(AC10="","",IF(AC10>=12,"Critical",IF(AC10>=8,"High",IF(AC10>=4,"Medium","Low"))))
C11: =IFERROR(INDEX('Inventory Template'!$B$3:$B$200,MATCH(B11,'Inventory Template'!$A$3:$A$200,0)),"") | AA11: =IF(OR(K11="",M11=""),"",K11*M11) | AB11: =IF(AA11="","",IF(AA11>=12,"Critical",IF(AA11>=8,"High",IF(AA11>=4,"Medium","Low")))) | AC11: =IF(OR(L11="",M11=""),"",L11*M11) | AD11: =IF(AC11="","",IF(AC11>=12,"Critical",IF(AC11>=8,"High",IF(AC11>=4,"Medium","Low"))))
C12: =IFERROR(INDEX('Inventory Template'!$B$3:$B$200,MATCH(B12,'Inventory Template'!$A$3:$A$200,0)),"") | AA12: =IF(OR(K12="",M12=""),"",K12*M12) | AB12: =IF(AA12="","",IF(AA12>=12,"Critical",IF(AA12>=8,"High",IF(AA12>=4,"Medium","Low")))) | AC12: =IF(OR(L12="",M12=""),"",L12*M12) | AD12: =IF(AC12="","",IF(AC12>=12,"Critical",IF(AC12>=8,"High",IF(AC12>=4,"Medium","Low"))))
C13: =IFERROR(INDEX('Inventory Template'!$B$3:$B$200,MATCH(B13,'Inventory Template'!$A$3:$A$200,0)),"") | AA13: =IF(OR(K13="",M13=""),"",K13*M13) | AB13: =IF(AA13="","",IF(AA13>=12,"Critical",IF(AA13>=8,"High",IF(AA13>=4,"Medium","Low")))) | AC13: =IF(OR(L13="",M13=""),"",L13*M13) | AD13: =IF(AC13="","",IF(AC13>=12,"Critical",IF(AC13>=8,"High",IF(AC13>=4,"Medium","Low"))))
C14: =IFERROR(INDEX('Inventory Template'!$B$3:$B$200,MATCH(B14,'Inventory Template'!$A$3:$A$200,0)),"") | AA14: =IF(OR(K14="",M14=""),"",K14*M14) | AB14: =IF(AA14="","",IF(AA14>=12,"Critical",IF(AA14>=8,"High",IF(AA14>=4,"Medium","Low")))) | AC14: =IF(OR(L14="",M14=""),"",L14*M14) | AD14: =IF(AC14="","",IF(AC14>=12,"Critical",IF(AC14>=8,"High",IF(AC14>=4,"Medium","Low"))))
C15: =IFERROR(INDEX('Inventory Template'!$B$3:$B$200,MATCH(B15,'Inventory Template'!$A$3:$A$200,0)),"") | AA15: =IF(OR(K15="",M15=""),"",K15*M15) | AB15: =IF(AA15="","",IF(AA15>=12,"Critical",IF(AA15>=8,"High",IF(AA15>=4,"Medium","Low")))) | AC15: =IF(OR(L15="",M15=""),"",L15*M15) | AD15: =IF(AC15="","",IF(AC15>=12,"Critical",IF(AC15>=8,"High",IF(AC15>=4,"Medium","Low"))))
... C33: =IFERROR(INDEX('Inventory Template'!$B$3:$B$200,MATCH(B33,'Inventory Template'!$A$3:$A$200,0)),"") | AA33: =IF(OR(K33="",M33=""),"",K33*M33) | AB33: =IF(AA33="","",IF(AA33>=12,"Critical",IF(AA33>=8,"High",IF(AA33>=4,"Medium","Low")))) | AC33: =IF(OR(L33="",M33=""),"",L33*M33) | AD33: =IF(AC33="","",IF(AC33>=12,"Critical",IF(AC33>=8,"High",IF(AC33>=4,"Medium","Low"))))
