Workbook

Sheet Read Me
B2: AI Vendor Assessment: questionnaire, contract clauses and decision
B3: AI Governance Series, Part 6: github.com/NarendraKarki/ai-governance
B5: What this workbook is for
B6: An AI tool you buy is several companies deep: the vendor's product, the foundation model inside it (usually from another company), the cloud it runs on, the vendor's subprocessors, and your own data at the centre. A vendor assessment asks what is in each layer before you sign, and turns every gap into a contract clause. This workbook holds the questions, the reason each one matters, the clause it needs, and a live status and decision.
B8: Normal due diligence vs AI vendor assessment
B9: A vendor can pass a normal security and supplier review and still be a risk, because that review checks the vendor, not the AI inside it. Column C marks each question: Standard due diligence (what a normal review already asks) or AI-specific (what it misses). The split is a judgement, not a legal category; mature questionnaires increasingly include AI questions.
B10: What it looks at | C10: Normal: the vendor as a company (security controls, certifications, financial standing, continuity). AI assessment: also every layer inside: the model and its maker, where prompts go, the model provider's own terms, how the data is used.
B11: Evidence | C11: Normal: security questionnaire, SOC 2 or ISO 27001 report, data processing agreement. AI assessment: those, plus the service terms, the subprocessor list and the model documentation.
B12: What it assumes | C12: Normal: the product is fixed once bought. AI assessment: the product can change underneath you: a new model, a different provider, an optional feature switched on.
B13: Data question | C13: Normal: is it encrypted, where is it stored, who can access it? AI assessment: also, does anyone keep it, review it or train on it, including the model provider; can it surface in another customer's results?
B14: Output | C14: Normal: not covered. AI assessment: accuracy, invented text, traceability to the source, and who carries the liability for a wrong output.
B15: New attack routes | C15: Normal: not covered. AI assessment: instructions hidden in uploaded documents (prompt injection), leakage through shared indexes or fine-tuning.
B16: When it is redone | C16: Normal: at renewal. AI assessment: at renewal, and on every model change, new subprocessor or newly enabled feature.
B18: What holds in most jurisdictions
B19: You stay responsible | C19: Most data protection laws leave the organisation that buys a service responsible for the vendor it chooses. Checking the vendor is the buyer's job.
B20: A contract with the vendor | C20: When a vendor processes personal data for you, many laws require a contract with it, and some set out what it must contain: what it may do, on whose instructions, how securely, and what happens at the end. Where yours does not, put these terms in anyway.
B21: Suppliers of the supplier | C21: Some laws, including the UK GDPR, require your approval before the vendor brings in its own suppliers (the model provider, the cloud host) and require them to be bound by the same terms. Where yours does not, the contract should.
B22: Data sent abroad | C22: Many laws restrict sending personal data to other countries; where yours does, each transfer needs a route it permits.
B23: Breaches | C23: Breaches must usually be reported quickly, so you depend on the vendor telling you fast.
B24: Why data protection law applies to client contracts | C24: Client contracts usually carry personal data: names, signatures, contact details, employees and guarantors. Where a document holds none, confidentiality, legal privilege and the client's own terms still apply, so the questions do not change.
B25: What the law rarely gives you | C25: Notice of model changes, the model's documentation, accuracy evidence, AI incident reporting and a fair liability cap mostly come only from the contract.
B27: The UK and EU, as a worked example
B28: You stay responsible | C28: When a vendor processes personal data for you, you may only use one that provides sufficient guarantees of appropriate technical and organisational measures (UK GDPR Art 28(1)). Using one that does not is your own breach: fines up to £8,700,000 or 2% of total worldwide annual turnover, whichever is higher (Art 83(4)(a)).
B29: The contract has set contents | C29: Processing must be governed by a contract with the terms in Art 28(3): documented instructions, confidentiality, security, subprocessor conditions, assistance, deletion or return at the end, and audit. Subprocessors need your prior written authorisation (Art 28(2)) and must be bound by the same terms (Art 28(4)).
B30: Training on your data | C30: A processor that, in breach of its role, decides to use your data for its own purposes, such as training its models, is treated as a controller for that processing (Art 28(10)). If the contract allows such use, you are disclosing client data to another controller and need your own basis to do so. Ask, and put the answer in the contract.
B31: Data leaving the UK | C31: Since 5 February 2026, transfers are governed by UK GDPR Art 44A (the old Art 44 was omitted by the Data (Use and Access) Act 2025): approved by regulations under Art 45A, subject to appropriate safeguards (Art 46), or a derogation (Art 49).
B32: Professional duties | C32: For a law firm: you keep the affairs of current and former clients confidential unless disclosure is required or permitted by law or the client consents (SRA Code of Conduct for Firms 6.3).
B33: What the EU AI Act does and does not give you | C33: Reviewing contracts for clients is not a high-risk use under Annex III (point 8(a) covers use by or on behalf of a judicial authority, and similar use in alternative dispute resolution), so the deployer duties in Art 26 do not apply to it. The provider of a general-purpose AI model must give documentation that gives a good understanding of the model's capabilities and limitations, with at least the Annex XII content, to the providers who integrate it, that is the vendor (Art 53(1)(b)); nothing obliges anyone to give it to you, and only its summary of training content is public (Art 53(1)(d)). For models placed on the market before 2 August 2025 this applies from 2 August 2027 (Art 111(3)). Deployers in the EU must take measures to support the AI literacy of staff who use AI (Art 4). Your leverage is the contract.
B34: If the tool is high-risk | C34: If the vendor intends the tool for an Annex III use, the deployer duties in Art 26 apply (use per the instructions, human oversight, monitoring, logs) and the vendor's own supply chain must be covered by written agreements (Art 25(4)). If you yourself put a tool not classified as high-risk to an Annex III use, you are treated as its provider, with the provider duties (Art 25(1)(c)). These apply to Annex III systems from 2 December 2027 (Art 113(c), as amended). Re-run question F1 whenever the way you use the tool changes.
B37: Using this outside the UK and EU
B38: The questions, the reasons in column E and the clauses are written to work in most jurisdictions. Column F shows the legal basis for one verified example, the UK and the EU. Map each row to your own data protection and AI law in column G, and have local counsel check it. Other jurisdictions may be added to the series once their texts have been checked.
B39: How to use it
B40: 1. Questionnaire | C40: Work in the Questionnaire Template sheet (keep a blank copy first). Fill column G for your jurisdiction. Send columns D and E to the vendor. Record each answer and the evidence you actually saw, not what was promised.
B41: 2. Rate | C41: Green: answer is adequate. Amber: a gap that can be fixed. Red: a gap that stops signing until fixed.
B42: 3. Contract | C42: For every Amber or Red, negotiate the clause in column K and mark whether it is secured (column L): in the signed contract or, for the firm's own items (F rows), done.
B43: 4. Status and decision | C43: Status is calculated: Red not secured is a blocker; Amber not secured is a condition before go-live. The Template Summary sheet gives the decision for your vendor; the Summary sheet shows the worked example.
B44: 5. Re-assess | C44: On renewal, on any model change (M2), on any new subprocessor (S2), and whenever the way you use the tool changes (F1).
B46: Colour key
B47: Yellow cells | C47: Cells to fill in on the template sheet.
B48: Red | C48: Rating
...

Sheet Summary
B2: Summary: worked example
B3: Live counts from the Questionnaire sheet (the worked example).
B5: Ratings by layer
B6: Layer | C6: Red | D6: Amber | E6: Green | F6: Total
B7: 1 Tool | C7: =COUNTIFS(Questionnaire!$B$4:$B$200,$B7,Questionnaire!$J$4:$J$200,"Red") -> 0 | D7: =COUNTIFS(Questionnaire!$B$4:$B$200,$B7,Questionnaire!$J$4:$J$200,"Amber") -> 5 | E7: =COUNTIFS(Questionnaire!$B$4:$B$200,$B7,Questionnaire!$J$4:$J$200,"Green") -> 7 | F7: =SUM(C7:E7) -> 12
B8: 2 Model | C8: =COUNTIFS(Questionnaire!$B$4:$B$200,$B8,Questionnaire!$J$4:$J$200,"Red") -> 0 | D8: =COUNTIFS(Questionnaire!$B$4:$B$200,$B8,Questionnaire!$J$4:$J$200,"Amber") -> 3 | E8: =COUNTIFS(Questionnaire!$B$4:$B$200,$B8,Questionnaire!$J$4:$J$200,"Green") -> 2 | F8: =SUM(C8:E8) -> 5
B9: 3 Hosting | C9: =COUNTIFS(Questionnaire!$B$4:$B$200,$B9,Questionnaire!$J$4:$J$200,"Red") -> 1 | D9: =COUNTIFS(Questionnaire!$B$4:$B$200,$B9,Questionnaire!$J$4:$J$200,"Amber") -> 1 | E9: =COUNTIFS(Questionnaire!$B$4:$B$200,$B9,Questionnaire!$J$4:$J$200,"Green") -> 4 | F9: =SUM(C9:E9) -> 6
B10: 4 Subprocessors | C10: =COUNTIFS(Questionnaire!$B$4:$B$200,$B10,Questionnaire!$J$4:$J$200,"Red") -> 1 | D10: =COUNTIFS(Questionnaire!$B$4:$B$200,$B10,Questionnaire!$J$4:$J$200,"Amber") -> 0 | E10: =COUNTIFS(Questionnaire!$B$4:$B$200,$B10,Questionnaire!$J$4:$J$200,"Green") -> 3 | F10: =SUM(C10:E10) -> 4
B11: 5 Data | C11: =COUNTIFS(Questionnaire!$B$4:$B$200,$B11,Questionnaire!$J$4:$J$200,"Red") -> 1 | D11: =COUNTIFS(Questionnaire!$B$4:$B$200,$B11,Questionnaire!$J$4:$J$200,"Amber") -> 0 | E11: =COUNTIFS(Questionnaire!$B$4:$B$200,$B11,Questionnaire!$J$4:$J$200,"Green") -> 3 | F11: =SUM(C11:E11) -> 4
B12: 6 The firm | C12: =COUNTIFS(Questionnaire!$B$4:$B$200,$B12,Questionnaire!$J$4:$J$200,"Red") -> 0 | D12: =COUNTIFS(Questionnaire!$B$4:$B$200,$B12,Questionnaire!$J$4:$J$200,"Amber") -> 1 | E12: =COUNTIFS(Questionnaire!$B$4:$B$200,$B12,Questionnaire!$J$4:$J$200,"Green") -> 2 | F12: =SUM(C12:E12) -> 3
B13: Total | C13: =SUM(C7:C12) -> 3 | D13: =SUM(D7:D12) -> 10 | E13: =SUM(E7:E12) -> 21 | F13: =SUM(F7:F12) -> 34
B15: Ratings by type: what a normal review asks, and what it misses
B16: Type | C16: Red | D16: Amber | E16: Green | F16: Questions
B17: Standard due diligence | C17: =COUNTIFS(Questionnaire!$C$4:$C$200,$B17,Questionnaire!$J$4:$J$200,"Red") -> 0 | D17: =COUNTIFS(Questionnaire!$C$4:$C$200,$B17,Questionnaire!$J$4:$J$200,"Amber") -> 3 | E17: =COUNTIFS(Questionnaire!$C$4:$C$200,$B17,Questionnaire!$J$4:$J$200,"Green") -> 16 | F17: =COUNTIF(Questionnaire!$C$4:$C$200,$B17) -> 19
B18: AI-specific | C18: =COUNTIFS(Questionnaire!$C$4:$C$200,$B18,Questionnaire!$J$4:$J$200,"Red") -> 3 | D18: =COUNTIFS(Questionnaire!$C$4:$C$200,$B18,Questionnaire!$J$4:$J$200,"Amber") -> 7 | E18: =COUNTIFS(Questionnaire!$C$4:$C$200,$B18,Questionnaire!$J$4:$J$200,"Green") -> 5 | F18: =COUNTIF(Questionnaire!$C$4:$C$200,$B18) -> 15
B20: Status
B21: Blockers: Red, not yet secured | C21: =COUNTIF(Questionnaire!$M$4:$M$200,"Blocker*") -> 0
B22: Conditions before go-live: Amber, not yet secured or done | C22: =COUNTIF(Questionnaire!$M$4:$M$200,"Condition*") -> 1
B23: Resolved: secured in the contract, or done | C23: =COUNTIF(Questionnaire!$M$4:$M$200,"Resolved") -> 12
B24: No action needed | C24: =COUNTIF(Questionnaire!$M$4:$M$200,"No action") -> 21
B26: Decision | C26: =IF(F13=0,"",IF(C21>0,"Do not sign yet",IF(F13<F17+F18,"Incomplete: "&(F17+F18-F13)&" not rated",IF(C22>0,"Sign: conditions before go-live","Sign")))) -> Sign: conditions before go-live

Sheet Questionnaire
A1: Questionnaire
A2: Worked example: Carrow Street Legal LLP (fictional) assessing a generative AI contract-review tool.
A3: ID | B3: Layer | C3: Type | D3: Question to the vendor | E3: Why it matters (general) | F3: Legal basis: UK and EU (worked example) | G3: Legal basis: your jurisdiction | H3: Vendor's answer | I3: Evidence seen | J3: Rating | K3: Clause the contract needs | L3: Secured (in the contract, or done)? | M3: Status | N3: Owner | O3: Follow-up
A4: T1 | B4: 1 Tool | C4: Standard due diligence | D4: What does the tool do with our documents, step by step, and for what purpose? | E4: The contract must say what the vendor may do with your data; you cannot write that without knowing the steps. | F4: The processor contract must set out the subject matter, duration, nature and purpose of the processing, the type of personal data and the categories of people (UK GDPR Art 28(3)). | H4: Clause extraction, risk flags and a summary per contract uploaded by fee earners. Purpose: review support only. | I4: Product description and data flow diagram | J4: Green | K4: Processing description schedule | L4: Yes | M4: =IF(J4="","",IF(J4="Green","No action",IF(L4="Yes","Resolved",IF(J4="Red","Blocker: do not sign","Condition before go-live")))) -> No action | N4: Head of Legal Technology | O4: -
A5: T2 | B5: 1 Tool | C5: Standard due diligence | D5: Will you sign a processor contract containing every Article 28(3) term? | E5: Many data protection laws require a contract when a vendor processes personal data for you, and some set out what it must contain. | F5: Processing on the firm's behalf must be governed by a binding contract with the terms in Art 28(3)(a) to (h). | H5: Standard DPA offered; one Art 28(3) term (audit) was missing in the first draft. | I5: DPA v3 | J5: Amber | K5: Data processing agreement | L5: Yes | M5: =IF(J5="","",IF(J5="Green","No action",IF(L5="Yes","Resolved",IF(J5="Red","Blocker: do not sign","Condition before go-live")))) -> Resolved | N5: General Counsel | O5: Audit term added in v3
A6: T3 | B6: 1 Tool | C6: Standard due diligence | D6: Do you process our data only on our documented instructions, including any transfer abroad? | E6: The vendor should act only on your instructions, including where the data goes. | F6: UK GDPR Art 28(3)(a). | H6: Yes, including transfers. | I6: DPA v3 clause 3 | J6: Green | K6: Instructions clause | L6: Yes | M6: =IF(J6="","",IF(J6="Green","No action",IF(L6="Yes","Resolved",IF(J6="Red","Blocker: do not sign","Condition before go-live")))) -> No action | N6: General Counsel | O6: -
A7: T4 | B7: 1 Tool | C7: Standard due diligence | D7: What independent evidence of your security can you show (audit reports, penetration test summaries)? | E7: In most jurisdictions you stay responsible for the vendor you choose. Ask for independent evidence, not assurances. | F7: The firm may use only processors providing sufficient guarantees (Art 28(1)); security appropriate to the risk (Art 32). | H7: Independent audit report for the last 12 months; penetration test summary from this year. | I7: Reports reviewed by the CISO | J7: Green | K7: Security schedule; right to updated evidence | L7: Yes | M7: =IF(J7="","",IF(J7="Green","No action",IF(L7="Yes","Resolved",IF(J7="Red","Blocker: do not sign","Condition before go-live")))) -> No action | N7: Chief Information Security Officer | O7: Refresh annually
A8: T5 | B8: 1 Tool | C8: Standard due diligence | D8: How quickly will you tell us about a personal data breach? | E8: Your own breach-reporting deadlines usually run from when you know; you depend on the vendor telling you fast. | F8: UK GDPR Art 33(2): a processor must notify the controller without undue delay after becoming aware of a breach. The firm's own 72-hour deadline runs under Art 33(1) and depends on it. | H8: Within 24 hours of becoming aware. | I8: DPA v3 clause 9 | J8: Green | K8: Breach notice within a fixed number of hours | L8: Yes | M8: =IF(J8="","",IF(J8="Green","No action",IF(L8="Yes","Resolved",IF(J8="Red","Blocker: do not sign","Condition before go-live")))) -> No action | N8: Data Protection Officer | O8: -
A9: T6 | B9: 1 Tool | C9: Standard due diligence | D9: Will you help us answer people's data requests and complete our DPIA? | E9: You will need the vendor's help to answer people's requests about their data and to assess the risks of the processing. | F9: UK GDPR Art 28(3)(e) and (f). | H9: Yes. | I9: DPA v3 clause 7 | J9: Green | K9: Assistance clause | L9: Yes | M9: =IF(J9="","",IF(J9="Green","No action",IF(L9="Yes","Resolved",IF(J9="Red","Blocker: do not sign","Condition before go-live")))) -> No action | N9: Data Protection Officer | O9: -
A10: T7 | B10: 1 Tool | C10: Standard due diligence | D10: When the contract ends, do you delete or return everything, including copies, and confirm it? | E10: At the end, your data and every copy should be deleted or returned, and that should be confirmed. | F10: UK GDPR Art 28(3)(g). | H10: Deletion within 30 days of exit, certificate on request. Logs were not covered at first. | I10: DPA v3 clause 12 | J10: Amber | K10: Exit: deletion or return, with certificate | L10: Yes | M10: =IF(J10="","",IF(J10="Green","No action",IF(L10="Yes","Resolved",IF(J10="Red","Blocker: do not sign","Condition before go-live")))) -> Resolved | N10: Data Protection Officer | O10: Logs now in scope (see H5)
A11: T8 | B11: 1 Tool | C11: Standard due diligence | D11: Will you allow audits, or provide the information needed to show compliance? | E11: You need a right to check what the vendor says it does. | F11: UK GDPR Art 28(3)(h). | H11: Annual audit report plus questionnaire; on-site audit only after an incident. | I11: DPA v3 clause 11 | J11: Green | K11: Audit and information rights | L11: Yes | M11: =IF(J11="","",IF(J11="Green","No action",IF(L11="Yes","Resolved",IF(J11="Red","Blocker: do not sign","Condition before go-live")))) -> No action | N11: General Counsel | O11: -
A12: T9 | B12: 1 Tool | C12: AI-specific | D12: Will you tell us about incidents and known failures that affect output quality or safety, not only personal data breaches? | E12: Few laws require a vendor to report AI failures to a customer; the contract can. | F12: No specific provision; contract only. | H12: Personal data breaches only at first; no commitment on model failures or quality incidents. | I12: DPA v3 clause 9 | J12: Amber | K12: AI incident notice | L12: Yes | M12: =IF(J12="","",IF(J12="Green","No action",IF(L12="Yes","Resolved",IF(J12="Red","Blocker: do not sign","Condition before go-live")))) -> Resolved | N12: General Counsel | O12: AI incident notice added: material output failures reported within 5 working days
A13: T10 | B13: 1 Tool | C13: Standard due diligence | D13: At exit, can we export our outputs, annotations and logs in a usable format, with a transition period? | E13: Deletion at exit protects the data; it does not give you your work product back. Only the contract does. | F13: UK GDPR Art 28(3)(g) covers deletion or return, not export of work product; contract only. | H13: Export of outputs and annotations in standard formats; 60-day transition period. | I13: Order form, exit schedule | J13: Green | K13: Exit assistance and data export | L13: Yes | M13: =IF(J13="","",IF(J13="Green","No action",IF(L13="Yes","Resolved",IF(J13="Red","Blocker: do not sign","Condition before go-live")))) -> No action | N13: Head of Legal Technology | O13: -
A14: T11 | B14: 1 Tool | C14: AI-specific | D14: What is your liability cap for data breaches and for errors in outputs, and does it match the risk to a regulated firm? | E14: A standard cap of a year's fees rarely covers a confidentiality breach or a claim that rests on a wrong output. | F14: No specific provision; contract only. | H14: Liability capped at 12 months' fees for everything, data breaches included. | I14: Master agreement v2 | J14: Amber | K14: Liability cap and indemnities | L14: Yes | M14: =IF(J14="","",IF(J14="Green","No action",IF(L14="Yes","Resolved",IF(J14="Red","Blocker: do not sign","Condition before go-live")))) -> Resolved | N14: General Counsel | O14: Separate, higher cap agreed for data protection and confidentiality breaches
A15: T12 | B15: 1 Tool | C15: AI-specific | D15: Which optional features change your data commitments (retention, human review, processing location), and who in our firm can switch them on? | E15: Some vendors' terms let optional features keep data, allow human review or process it outside the agreed region. A secure core product can be changed by an administrator's setting. | F15: No specific provision; contract and admin controls. | H15: Two optional features (web search and an external model) process data outside the agreed region and allow provider safety review; both off by default; any administrator could enable them. | I15: Service terms, admin settings | J15: Amber | K15: Optional features that change data commitments stay off unless approved in writing | L15: Yes | M15: =IF(J15="","",IF(J15="Green","No action",IF(L15="Yes","Resolved",IF(J15="Red","Blocker: do not sign","Condition before go-live")))) -> Resolved | N15: Head of Legal Technology | O15: Contract: off unless the DPO approves in writing; admin rights limited to two named people
... A37: F3 | B37: 6 The firm | C37: Standard due diligence | D37: Does this use need an impact assessment? | E37: Many data protection laws require a risk assessment before high-risk processing. | F37: UK GDPR Art 35; the Part 5 workbook does the screen. | H37: Screened: client personal data at scale; DPIA required and completed. | I37: DPIA | J37: Green | K37: Not a clause: DPIA screening record | L37: Yes | M37: =IF(J37="","",IF(J37="Green","No action",IF(L37="Yes","Resolved",IF(J37="Red","Blocker: do not sign","Condition before go-live")))) -> No action | N37: Data Protection Officer | O37: -

Sheet Template Summary
B2: Template Summary: your vendor
B3: Live counts and decision from the Questionnaire Template sheet. Blank until ratings are entered.
B5: Ratings by layer
B6: Layer | C6: Red | D6: Amber | E6: Green | F6: Total
B7: 1 Tool | C7: =COUNTIFS('Questionnaire Template'!$B$4:$B$200,$B7,'Questionnaire Template'!$J$4:$J$200,"Red") -> 0 | D7: =COUNTIFS('Questionnaire Template'!$B$4:$B$200,$B7,'Questionnaire Template'!$J$4:$J$200,"Amber") -> 0 | E7: =COUNTIFS('Questionnaire Template'!$B$4:$B$200,$B7,'Questionnaire Template'!$J$4:$J$200,"Green") -> 0 | F7: =SUM(C7:E7) -> 0
B8: 2 Model | C8: =COUNTIFS('Questionnaire Template'!$B$4:$B$200,$B8,'Questionnaire Template'!$J$4:$J$200,"Red") -> 0 | D8: =COUNTIFS('Questionnaire Template'!$B$4:$B$200,$B8,'Questionnaire Template'!$J$4:$J$200,"Amber") -> 0 | E8: =COUNTIFS('Questionnaire Template'!$B$4:$B$200,$B8,'Questionnaire Template'!$J$4:$J$200,"Green") -> 0 | F8: =SUM(C8:E8) -> 0
B9: 3 Hosting | C9: =COUNTIFS('Questionnaire Template'!$B$4:$B$200,$B9,'Questionnaire Template'!$J$4:$J$200,"Red") -> 0 | D9: =COUNTIFS('Questionnaire Template'!$B$4:$B$200,$B9,'Questionnaire Template'!$J$4:$J$200,"Amber") -> 0 | E9: =COUNTIFS('Questionnaire Template'!$B$4:$B$200,$B9,'Questionnaire Template'!$J$4:$J$200,"Green") -> 0 | F9: =SUM(C9:E9) -> 0
B10: 4 Subprocessors | C10: =COUNTIFS('Questionnaire Template'!$B$4:$B$200,$B10,'Questionnaire Template'!$J$4:$J$200,"Red") -> 0 | D10: =COUNTIFS('Questionnaire Template'!$B$4:$B$200,$B10,'Questionnaire Template'!$J$4:$J$200,"Amber") -> 0 | E10: =COUNTIFS('Questionnaire Template'!$B$4:$B$200,$B10,'Questionnaire Template'!$J$4:$J$200,"Green") -> 0 | F10: =SUM(C10:E10) -> 0
B11: 5 Data | C11: =COUNTIFS('Questionnaire Template'!$B$4:$B$200,$B11,'Questionnaire Template'!$J$4:$J$200,"Red") -> 0 | D11: =COUNTIFS('Questionnaire Template'!$B$4:$B$200,$B11,'Questionnaire Template'!$J$4:$J$200,"Amber") -> 0 | E11: =COUNTIFS('Questionnaire Template'!$B$4:$B$200,$B11,'Questionnaire Template'!$J$4:$J$200,"Green") -> 0 | F11: =SUM(C11:E11) -> 0
B12: 6 The firm | C12: =COUNTIFS('Questionnaire Template'!$B$4:$B$200,$B12,'Questionnaire Template'!$J$4:$J$200,"Red") -> 0 | D12: =COUNTIFS('Questionnaire Template'!$B$4:$B$200,$B12,'Questionnaire Template'!$J$4:$J$200,"Amber") -> 0 | E12: =COUNTIFS('Questionnaire Template'!$B$4:$B$200,$B12,'Questionnaire Template'!$J$4:$J$200,"Green") -> 0 | F12: =SUM(C12:E12) -> 0
B13: Total | C13: =SUM(C7:C12) -> 0 | D13: =SUM(D7:D12) -> 0 | E13: =SUM(E7:E12) -> 0 | F13: =SUM(F7:F12) -> 0
B15: Ratings by type: what a normal review asks, and what it misses
B16: Type | C16: Red | D16: Amber | E16: Green | F16: Questions
B17: Standard due diligence | C17: =COUNTIFS('Questionnaire Template'!$C$4:$C$200,$B17,'Questionnaire Template'!$J$4:$J$200,"Red") -> 0 | D17: =COUNTIFS('Questionnaire Template'!$C$4:$C$200,$B17,'Questionnaire Template'!$J$4:$J$200,"Amber") -> 0 | E17: =COUNTIFS('Questionnaire Template'!$C$4:$C$200,$B17,'Questionnaire Template'!$J$4:$J$200,"Green") -> 0 | F17: =COUNTIF('Questionnaire Template'!$C$4:$C$200,$B17) -> 19
B18: AI-specific | C18: =COUNTIFS('Questionnaire Template'!$C$4:$C$200,$B18,'Questionnaire Template'!$J$4:$J$200,"Red") -> 0 | D18: =COUNTIFS('Questionnaire Template'!$C$4:$C$200,$B18,'Questionnaire Template'!$J$4:$J$200,"Amber") -> 0 | E18: =COUNTIFS('Questionnaire Template'!$C$4:$C$200,$B18,'Questionnaire Template'!$J$4:$J$200,"Green") -> 0 | F18: =COUNTIF('Questionnaire Template'!$C$4:$C$200,$B18) -> 15
B20: Status
B21: Blockers: Red, not yet secured | C21: =COUNTIF('Questionnaire Template'!$M$4:$M$200,"Blocker*") -> 0
B22: Conditions before go-live: Amber, not yet secured or done | C22: =COUNTIF('Questionnaire Template'!$M$4:$M$200,"Condition*") -> 0
B23: Resolved: secured in the contract, or done | C23: =COUNTIF('Questionnaire Template'!$M$4:$M$200,"Resolved") -> 0
B24: No action needed | C24: =COUNTIF('Questionnaire Template'!$M$4:$M$200,"No action") -> 0
B26: Decision | C26: =IF(F13=0,"",IF(C21>0,"Do not sign yet",IF(F13<F17+F18,"Incomplete: "&(F17+F18-F13)&" not rated",IF(C22>0,"Sign: conditions before go-live","Sign"))))

Sheet Questionnaire Template
A1: Questionnaire Template
A2: Fill the yellow cells. Rating: Green (answer is adequate), Amber (gap, fixable), Red (gap that stops signing). Status is calculated; the Template Summary sheet gives the decision.
A3: ID | B3: Layer | C3: Type | D3: Question to the vendor | E3: Why it matters (general) | F3: Legal basis: UK and EU (worked example) | G3: Legal basis: your jurisdiction | H3: Vendor's answer | I3: Evidence seen | J3: Rating | K3: Clause the contract needs | L3: Secured (in the contract, or done)? | M3: Status | N3: Owner | O3: Follow-up
A4: T1 | B4: 1 Tool | C4: Standard due diligence | D4: What does the tool do with our documents, step by step, and for what purpose? | E4: The contract must say what the vendor may do with your data; you cannot write that without knowing the steps. | F4: The processor contract must set out the subject matter, duration, nature and purpose of the processing, the type of personal data and the categories of people (UK GDPR Art 28(3)). | K4: Processing description schedule | M4: =IF(J4="","",IF(J4="Green","No action",IF(L4="Yes","Resolved",IF(J4="Red","Blocker: do not sign","Condition before go-live"))))
A5: T2 | B5: 1 Tool | C5: Standard due diligence | D5: Will you sign a processor contract containing every Article 28(3) term? | E5: Many data protection laws require a contract when a vendor processes personal data for you, and some set out what it must contain. | F5: Processing on the firm's behalf must be governed by a binding contract with the terms in Art 28(3)(a) to (h). | K5: Data processing agreement | M5: =IF(J5="","",IF(J5="Green","No action",IF(L5="Yes","Resolved",IF(J5="Red","Blocker: do not sign","Condition before go-live"))))
A6: T3 | B6: 1 Tool | C6: Standard due diligence | D6: Do you process our data only on our documented instructions, including any transfer abroad? | E6: The vendor should act only on your instructions, including where the data goes. | F6: UK GDPR Art 28(3)(a). | K6: Instructions clause | M6: =IF(J6="","",IF(J6="Green","No action",IF(L6="Yes","Resolved",IF(J6="Red","Blocker: do not sign","Condition before go-live"))))
A7: T4 | B7: 1 Tool | C7: Standard due diligence | D7: What independent evidence of your security can you show (audit reports, penetration test summaries)? | E7: In most jurisdictions you stay responsible for the vendor you choose. Ask for independent evidence, not assurances. | F7: The firm may use only processors providing sufficient guarantees (Art 28(1)); security appropriate to the risk (Art 32). | K7: Security schedule; right to updated evidence | M7: =IF(J7="","",IF(J7="Green","No action",IF(L7="Yes","Resolved",IF(J7="Red","Blocker: do not sign","Condition before go-live"))))
A8: T5 | B8: 1 Tool | C8: Standard due diligence | D8: How quickly will you tell us about a personal data breach? | E8: Your own breach-reporting deadlines usually run from when you know; you depend on the vendor telling you fast. | F8: UK GDPR Art 33(2): a processor must notify the controller without undue delay after becoming aware of a breach. The firm's own 72-hour deadline runs under Art 33(1) and depends on it. | K8: Breach notice within a fixed number of hours | M8: =IF(J8="","",IF(J8="Green","No action",IF(L8="Yes","Resolved",IF(J8="Red","Blocker: do not sign","Condition before go-live"))))
A9: T6 | B9: 1 Tool | C9: Standard due diligence | D9: Will you help us answer people's data requests and complete our DPIA? | E9: You will need the vendor's help to answer people's requests about their data and to assess the risks of the processing. | F9: UK GDPR Art 28(3)(e) and (f). | K9: Assistance clause | M9: =IF(J9="","",IF(J9="Green","No action",IF(L9="Yes","Resolved",IF(J9="Red","Blocker: do not sign","Condition before go-live"))))
A10: T7 | B10: 1 Tool | C10: Standard due diligence | D10: When the contract ends, do you delete or return everything, including copies, and confirm it? | E10: At the end, your data and every copy should be deleted or returned, and that should be confirmed. | F10: UK GDPR Art 28(3)(g). | K10: Exit: deletion or return, with certificate | M10: =IF(J10="","",IF(J10="Green","No action",IF(L10="Yes","Resolved",IF(J10="Red","Blocker: do not sign","Condition before go-live"))))
A11: T8 | B11: 1 Tool | C11: Standard due diligence | D11: Will you allow audits, or provide the information needed to show compliance? | E11: You need a right to check what the vendor says it does. | F11: UK GDPR Art 28(3)(h). | K11: Audit and information rights | M11: =IF(J11="","",IF(J11="Green","No action",IF(L11="Yes","Resolved",IF(J11="Red","Blocker: do not sign","Condition before go-live"))))
A12: T9 | B12: 1 Tool | C12: AI-specific | D12: Will you tell us about incidents and known failures that affect output quality or safety, not only personal data breaches? | E12: Few laws require a vendor to report AI failures to a customer; the contract can. | F12: No specific provision; contract only. | K12: AI incident notice | M12: =IF(J12="","",IF(J12="Green","No action",IF(L12="Yes","Resolved",IF(J12="Red","Blocker: do not sign","Condition before go-live"))))
A13: T10 | B13: 1 Tool | C13: Standard due diligence | D13: At exit, can we export our outputs, annotations and logs in a usable format, with a transition period? | E13: Deletion at exit protects the data; it does not give you your work product back. Only the contract does. | F13: UK GDPR Art 28(3)(g) covers deletion or return, not export of work product; contract only. | K13: Exit assistance and data export | M13: =IF(J13="","",IF(J13="Green","No action",IF(L13="Yes","Resolved",IF(J13="Red","Blocker: do not sign","Condition before go-live"))))
A14: T11 | B14: 1 Tool | C14: AI-specific | D14: What is your liability cap for data breaches and for errors in outputs, and does it match the risk to a regulated firm? | E14: A standard cap of a year's fees rarely covers a confidentiality breach or a claim that rests on a wrong output. | F14: No specific provision; contract only. | K14: Liability cap and indemnities | M14: =IF(J14="","",IF(J14="Green","No action",IF(L14="Yes","Resolved",IF(J14="Red","Blocker: do not sign","Condition before go-live"))))
A15: T12 | B15: 1 Tool | C15: AI-specific | D15: Which optional features change your data commitments (retention, human review, processing location), and who in our firm can switch them on? | E15: Some vendors' terms let optional features keep data, allow human review or process it outside the agreed region. A secure core product can be changed by an administrator's setting. | F15: No specific provision; contract and admin controls. | K15: Optional features that change data commitments stay off unless approved in writing | M15: =IF(J15="","",IF(J15="Green","No action",IF(L15="Yes","Resolved",IF(J15="Red","Blocker: do not sign","Condition before go-live"))))
... A37: F3 | B37: 6 The firm | C37: Standard due diligence | D37: Does this use need an impact assessment? | E37: Many data protection laws require a risk assessment before high-risk processing. | F37: UK GDPR Art 35; the Part 5 workbook does the screen. | K37: Not a clause: DPIA screening record | M37: =IF(J37="","",IF(J37="Green","No action",IF(L37="Yes","Resolved",IF(J37="Red","Blocker: do not sign","Condition before go-live"))))
